Traceback (most recent call last):
  File "C:\Users\Eliana Gomez\miniconda3\envs\Empresa\lib\site-packages\jupyter_cache\executors\utils.py", line 58, in single_nb_execution
    executenb(
  File "C:\Users\Eliana Gomez\miniconda3\envs\Empresa\lib\site-packages\nbclient\client.py", line 1314, in execute
    return NotebookClient(nb=nb, resources=resources, km=km, **kwargs).execute()
  File "C:\Users\Eliana Gomez\miniconda3\envs\Empresa\lib\site-packages\jupyter_core\utils\__init__.py", line 165, in wrapped
    return loop.run_until_complete(inner)
  File "C:\Users\Eliana Gomez\miniconda3\envs\Empresa\lib\asyncio\base_events.py", line 647, in run_until_complete
    return future.result()
  File "C:\Users\Eliana Gomez\miniconda3\envs\Empresa\lib\site-packages\nbclient\client.py", line 709, in async_execute
    await self.async_execute_cell(
  File "C:\Users\Eliana Gomez\miniconda3\envs\Empresa\lib\site-packages\nbclient\client.py", line 1062, in async_execute_cell
    await self._check_raise_for_error(cell, cell_index, exec_reply)
  File "C:\Users\Eliana Gomez\miniconda3\envs\Empresa\lib\site-packages\nbclient\client.py", line 918, in _check_raise_for_error
    raise CellExecutionError.from_cell_and_msg(cell, exec_reply_content)
nbclient.exceptions.CellExecutionError: An error occurred while executing the following cell:
------------------
try:
    connection = psycopg2.connect(user="Elianna_user",
                                  password="password",
                                  host="localhost",
                                  port="5432",
                                  database="Elianna_db")

    cursor = connection.cursor()
    print("PostgreSQL server information")
    print(connection.get_dsn_parameters(), "\n")

    cursor.execute("SELECT version();")
    record = cursor.fetchone()
    print("You are connected to - ", record, "\n")

except (Exception, Error) as error:
    print("Error while connecting to PostgreSQL", error)
finally:
    if (connection):
        cursor.close()
        connection.close()
        print("PostgreSQL connection is closed")
------------------


[1;31m---------------------------------------------------------------------------[0m
[1;31mNameError[0m                                 Traceback (most recent call last)
Cell [1;32mIn[1], line 2[0m
[0;32m      1[0m [38;5;28;01mtry[39;00m:
[1;32m----> 2[0m     connection [38;5;241m=[39m [43mpsycopg2[49m[38;5;241m.[39mconnect(user[38;5;241m=[39m[38;5;124m"[39m[38;5;124mElianna_user[39m[38;5;124m"[39m,
[0;32m      3[0m                                   password[38;5;241m=[39m[38;5;124m"[39m[38;5;124mpassword[39m[38;5;124m"[39m,
[0;32m      4[0m                                   host[38;5;241m=[39m[38;5;124m"[39m[38;5;124mlocalhost[39m[38;5;124m"[39m,
[0;32m      5[0m                                   port[38;5;241m=[39m[38;5;124m"[39m[38;5;124m5432[39m[38;5;124m"[39m,
[0;32m      6[0m                                   database[38;5;241m=[39m[38;5;124m"[39m[38;5;124mElianna_db[39m[38;5;124m"[39m)
[0;32m      8[0m     cursor [38;5;241m=[39m connection[38;5;241m.[39mcursor()

[1;31mNameError[0m: name 'psycopg2' is not defined

During handling of the above exception, another exception occurred:

[1;31mNameError[0m                                 Traceback (most recent call last)
Cell [1;32mIn[1], line 16[0m
[0;32m     14[0m     [38;5;28mprint[39m([38;5;124m"[39m[38;5;124mYou are connected to - [39m[38;5;124m"[39m, record, [38;5;124m"[39m[38;5;130;01m\n[39;00m[38;5;124m"[39m)
[1;32m---> 16[0m [38;5;28;01mexcept[39;00m ([38;5;167;01mException[39;00m, [43mError[49m) [38;5;28;01mas[39;00m error:
[0;32m     17[0m     [38;5;28mprint[39m([38;5;124m"[39m[38;5;124mError while connecting to PostgreSQL[39m[38;5;124m"[39m, error)

[1;31mNameError[0m: name 'Error' is not defined

During handling of the above exception, another exception occurred:

[1;31mNameError[0m                                 Traceback (most recent call last)
Cell [1;32mIn[1], line 19[0m
[0;32m     17[0m     [38;5;28mprint[39m([38;5;124m"[39m[38;5;124mError while connecting to PostgreSQL[39m[38;5;124m"[39m, error)
[0;32m     18[0m [38;5;28;01mfinally[39;00m:
[1;32m---> 19[0m     [38;5;28;01mif[39;00m ([43mconnection[49m):
[0;32m     20[0m         cursor[38;5;241m.[39mclose()
[0;32m     21[0m         connection[38;5;241m.[39mclose()

[1;31mNameError[0m: name 'connection' is not defined

